2024-11-26 23:03:15 | ERROR | El procedimiento no insertó el usuario.
2024-11-26 23:03:15 | ERROR | Traceback (most recent call last):
  File "/home/angel/Documentos/repositorios/api_flask_ecommerce/src/services/UsuariosService.py", line 50, in agregar_usuario
    raise Exception("El procedimiento no insertó el usuario.")
Exception: El procedimiento no insertó el usuario.

2024-11-26 23:11:31 | ERROR | El procedimiento no insertó el usuario.
2024-11-26 23:11:31 | ERROR | Traceback (most recent call last):
  File "/home/angel/Documentos/repositorios/api_flask_ecommerce/src/services/UsuariosService.py", line 51, in agregar_usuario
    raise Exception("El procedimiento no insertó el usuario.")
Exception: El procedimiento no insertó el usuario.

2024-11-26 23:14:03 | ERROR | El procedimiento no insertó el usuario.
2024-11-26 23:14:03 | ERROR | Traceback (most recent call last):
  File "/home/angel/Documentos/repositorios/api_flask_ecommerce/src/services/UsuariosService.py", line 51, in agregar_usuario
    raise Exception("El procedimiento no insertó el usuario.")
Exception: El procedimiento no insertó el usuario.

2024-11-26 23:14:44 | ERROR | El procedimiento no insertó el usuario.
2024-11-26 23:14:44 | ERROR | Traceback (most recent call last):
  File "/home/angel/Documentos/repositorios/api_flask_ecommerce/src/services/UsuariosService.py", line 51, in agregar_usuario
    raise Exception("El procedimiento no insertó el usuario.")
Exception: El procedimiento no insertó el usuario.

2024-11-26 23:25:15 | ERROR | 'NoneType' object has no attribute 'cursor'
2024-11-26 23:25:15 | ERROR | Traceback (most recent call last):
  File "/home/angel/Documentos/repositorios/api_flask_ecommerce/src/services/AuthService.py", line 18, in login_user
    with connection.cursor() as cursor:
         ^^^^^^^^^^^^^^^^^
AttributeError: 'NoneType' object has no attribute 'cursor'

2024-11-26 23:25:22 | ERROR | 'NoneType' object has no attribute 'cursor'
2024-11-26 23:25:22 | ERROR | Traceback (most recent call last):
  File "/home/angel/Documentos/repositorios/api_flask_ecommerce/src/services/AuthService.py", line 18, in login_user
    with connection.cursor() as cursor:
         ^^^^^^^^^^^^^^^^^
AttributeError: 'NoneType' object has no attribute 'cursor'

2024-11-26 23:25:46 | ERROR | 'NoneType' object has no attribute 'cursor'
2024-11-26 23:25:46 | ERROR | Traceback (most recent call last):
  File "/home/angel/Documentos/repositorios/api_flask_ecommerce/src/services/AuthService.py", line 18, in login_user
    with connection.cursor() as cursor:
         ^^^^^^^^^^^^^^^^^
AttributeError: 'NoneType' object has no attribute 'cursor'

2024-11-26 23:26:21 | ERROR | 'NoneType' object has no attribute 'cursor'
2024-11-26 23:26:21 | ERROR | Traceback (most recent call last):
  File "/home/angel/Documentos/repositorios/api_flask_ecommerce/src/services/AuthService.py", line 18, in login_user
    with connection.cursor() as cursor:
         ^^^^^^^^^^^^^^^^^
AttributeError: 'NoneType' object has no attribute 'cursor'

2024-11-26 23:26:50 | ERROR | 'NoneType' object has no attribute 'cursor'
2024-11-26 23:26:50 | ERROR | Traceback (most recent call last):
  File "/home/angel/Documentos/repositorios/api_flask_ecommerce/src/services/AuthService.py", line 18, in login_user
    with connection.cursor() as cursor:
         ^^^^^^^^^^^^^^^^^
AttributeError: 'NoneType' object has no attribute 'cursor'

2024-11-26 23:29:41 | ERROR | El procedimiento no insertó el usuario.
2024-11-26 23:29:41 | ERROR | Traceback (most recent call last):
  File "/home/angel/Documentos/repositorios/api_flask_ecommerce/src/services/UsuariosService.py", line 51, in agregar_usuario
    raise Exception("El procedimiento no insertó el usuario.")
Exception: El procedimiento no insertó el usuario.

2024-11-26 23:39:00 | ERROR | El procedimiento no insertó el usuario.
2024-11-26 23:39:00 | ERROR | Traceback (most recent call last):
  File "/home/angel/Documentos/repositorios/api_flask_ecommerce/src/services/UsuariosService.py", line 52, in agregar_usuario
    raise Exception("El procedimiento no insertó el usuario.")
Exception: El procedimiento no insertó el usuario.

2024-11-26 23:42:12 | ERROR | El procedimiento no insertó el usuario.
2024-11-26 23:42:12 | ERROR | Traceback (most recent call last):
  File "/home/angel/Documentos/repositorios/api_flask_ecommerce/src/services/UsuariosService.py", line 52, in agregar_usuario
    raise Exception("El procedimiento no insertó el usuario.")
Exception: El procedimiento no insertó el usuario.

2024-11-27 00:04:54 | ERROR | El procedimiento no insertó el usuario.
2024-11-27 00:04:54 | ERROR | Traceback (most recent call last):
  File "/home/angel/Documentos/repositorios/api_flask_ecommerce/src/services/UsuariosService.py", line 52, in agregar_usuario
    raise Exception("El procedimiento no insertó el usuario.")
Exception: El procedimiento no insertó el usuario.

2024-11-27 00:07:04 | ERROR | El procedimiento no insertó el usuario.
2024-11-27 00:07:04 | ERROR | Traceback (most recent call last):
  File "/home/angel/Documentos/repositorios/api_flask_ecommerce/src/services/UsuariosService.py", line 52, in agregar_usuario
    raise Exception("El procedimiento no insertó el usuario.")
Exception: El procedimiento no insertó el usuario.

2024-11-27 00:10:26 | ERROR | El procedimiento no insertó el usuario.
2024-11-27 00:10:26 | ERROR | Traceback (most recent call last):
  File "/home/angel/Documentos/repositorios/api_flask_ecommerce/src/services/UsuariosService.py", line 52, in agregar_usuario
    raise Exception("El procedimiento no insertó el usuario.")
Exception: El procedimiento no insertó el usuario.

2024-11-27 00:12:54 | ERROR | not enough arguments for format string
2024-11-27 00:12:54 | ERROR | Traceback (most recent call last):
  File "/home/angel/Documentos/repositorios/api_flask_ecommerce/src/services/UsuariosService.py", line 47, in agregar_usuario
    cursor.callproc('call agregar_usuario(%s, %s, %s, %s)',
  File "/home/angel/Documentos/repositorios/api_flask_ecommerce/.api_venv/lib/python3.11/site-packages/pymysql/cursors.py", line 259, in callproc
    % ",".join(
      ^^^^^^^^^
  File "/home/angel/Documentos/repositorios/api_flask_ecommerce/.api_venv/lib/python3.11/site-packages/pymysql/cursors.py", line 260, in <genexpr>
    fmt % (index, conn.escape(arg)) for index, arg in enumerate(args)
    ~~~~^~~~~~~~~~~~~~~~~~~~~~~~~~~
TypeError: not enough arguments for format string

2024-11-27 00:17:03 | ERROR | El procedimiento no insertó el usuario.
2024-11-27 00:17:03 | ERROR | Traceback (most recent call last):
  File "/home/angel/Documentos/repositorios/api_flask_ecommerce/src/services/UsuariosService.py", line 51, in agregar_usuario
    raise Exception("El procedimiento no insertó el usuario.")
Exception: El procedimiento no insertó el usuario.

2024-11-27 00:30:24 | ERROR | El procedimiento no insertó el usuario.
2024-11-27 00:30:24 | ERROR | Traceback (most recent call last):
  File "/home/angel/Documentos/repositorios/api_flask_ecommerce/src/services/UsuariosService.py", line 51, in agregar_usuario
    raise Exception("El procedimiento no insertó el usuario.")
Exception: El procedimiento no insertó el usuario.

2024-11-27 00:34:17 | ERROR | 400 Bad Request: Failed to decode JSON object: Expecting ',' delimiter: line 2 column 17 (char 18)
2024-11-27 00:34:17 | ERROR | Traceback (most recent call last):
  File "/home/angel/Documentos/repositorios/api_flask_ecommerce/.api_venv/lib/python3.11/site-packages/werkzeug/wrappers/request.py", line 611, in get_json
    rv = self.json_module.loads(data)
         ^^^^^^^^^^^^^^^^^^^^^^^^^^^^
  File "/home/angel/Documentos/repositorios/api_flask_ecommerce/.api_venv/lib/python3.11/site-packages/flask/json/provider.py", line 187, in loads
    return json.loads(s, **kwargs)
           ^^^^^^^^^^^^^^^^^^^^^^^
  File "/usr/lib/python3.11/json/__init__.py", line 346, in loads
    return _default_decoder.decode(s)
           ^^^^^^^^^^^^^^^^^^^^^^^^^^
  File "/usr/lib/python3.11/json/decoder.py", line 337, in decode
    obj, end = self.raw_decode(s, idx=_w(s, 0).end())
               ^^^^^^^^^^^^^^^^^^^^^^^^^^^^^^^^^^^^^^
  File "/usr/lib/python3.11/json/decoder.py", line 353, in raw_decode
    obj, end = self.scan_once(s, idx)
               ^^^^^^^^^^^^^^^^^^^^^^
json.decoder.JSONDecodeError: Expecting ',' delimiter: line 2 column 17 (char 18)

During handling of the above exception, another exception occurred:

Traceback (most recent call last):
  File "/home/angel/Documentos/repositorios/api_flask_ecommerce/src/routes/UsuariosRoutes.py", line 93, in eliminar_usuario
    if not request.json:
           ^^^^^^^^^^^^
  File "/home/angel/Documentos/repositorios/api_flask_ecommerce/.api_venv/lib/python3.11/site-packages/werkzeug/wrappers/request.py", line 560, in json
    return self.get_json()
           ^^^^^^^^^^^^^^^
  File "/home/angel/Documentos/repositorios/api_flask_ecommerce/.api_venv/lib/python3.11/site-packages/werkzeug/wrappers/request.py", line 620, in get_json
    rv = self.on_json_loading_failed(e)
         ^^^^^^^^^^^^^^^^^^^^^^^^^^^^^^
  File "/home/angel/Documentos/repositorios/api_flask_ecommerce/.api_venv/lib/python3.11/site-packages/flask/wrappers.py", line 214, in on_json_loading_failed
    return super().on_json_loading_failed(e)
           ^^^^^^^^^^^^^^^^^^^^^^^^^^^^^^^^^
  File "/home/angel/Documentos/repositorios/api_flask_ecommerce/.api_venv/lib/python3.11/site-packages/werkzeug/wrappers/request.py", line 645, in on_json_loading_failed
    raise BadRequest(f"Failed to decode JSON object: {e}")
werkzeug.exceptions.BadRequest: 400 Bad Request: Failed to decode JSON object: Expecting ',' delimiter: line 2 column 17 (char 18)

2024-11-27 00:35:47 | ERROR | El procedimiento no insertó el usuario.
2024-11-27 00:35:47 | ERROR | Traceback (most recent call last):
  File "/home/angel/Documentos/repositorios/api_flask_ecommerce/src/services/UsuariosService.py", line 51, in agregar_usuario
    raise Exception("El procedimiento no insertó el usuario.")
Exception: El procedimiento no insertó el usuario.

2024-11-27 00:37:48 | ERROR | 400 Bad Request: Failed to decode JSON object: Expecting ',' delimiter: line 2 column 17 (char 18)
2024-11-27 00:37:48 | ERROR | Traceback (most recent call last):
  File "/home/angel/Documentos/repositorios/api_flask_ecommerce/.api_venv/lib/python3.11/site-packages/werkzeug/wrappers/request.py", line 611, in get_json
    rv = self.json_module.loads(data)
         ^^^^^^^^^^^^^^^^^^^^^^^^^^^^
  File "/home/angel/Documentos/repositorios/api_flask_ecommerce/.api_venv/lib/python3.11/site-packages/flask/json/provider.py", line 187, in loads
    return json.loads(s, **kwargs)
           ^^^^^^^^^^^^^^^^^^^^^^^
  File "/usr/lib/python3.11/json/__init__.py", line 346, in loads
    return _default_decoder.decode(s)
           ^^^^^^^^^^^^^^^^^^^^^^^^^^
  File "/usr/lib/python3.11/json/decoder.py", line 337, in decode
    obj, end = self.raw_decode(s, idx=_w(s, 0).end())
               ^^^^^^^^^^^^^^^^^^^^^^^^^^^^^^^^^^^^^^
  File "/usr/lib/python3.11/json/decoder.py", line 353, in raw_decode
    obj, end = self.scan_once(s, idx)
               ^^^^^^^^^^^^^^^^^^^^^^
json.decoder.JSONDecodeError: Expecting ',' delimiter: line 2 column 17 (char 18)

During handling of the above exception, another exception occurred:

Traceback (most recent call last):
  File "/home/angel/Documentos/repositorios/api_flask_ecommerce/src/routes/UsuariosRoutes.py", line 93, in eliminar_usuario
    if not request.json:
           ^^^^^^^^^^^^
  File "/home/angel/Documentos/repositorios/api_flask_ecommerce/.api_venv/lib/python3.11/site-packages/werkzeug/wrappers/request.py", line 560, in json
    return self.get_json()
           ^^^^^^^^^^^^^^^
  File "/home/angel/Documentos/repositorios/api_flask_ecommerce/.api_venv/lib/python3.11/site-packages/werkzeug/wrappers/request.py", line 620, in get_json
    rv = self.on_json_loading_failed(e)
         ^^^^^^^^^^^^^^^^^^^^^^^^^^^^^^
  File "/home/angel/Documentos/repositorios/api_flask_ecommerce/.api_venv/lib/python3.11/site-packages/flask/wrappers.py", line 214, in on_json_loading_failed
    return super().on_json_loading_failed(e)
           ^^^^^^^^^^^^^^^^^^^^^^^^^^^^^^^^^
  File "/home/angel/Documentos/repositorios/api_flask_ecommerce/.api_venv/lib/python3.11/site-packages/werkzeug/wrappers/request.py", line 645, in on_json_loading_failed
    raise BadRequest(f"Failed to decode JSON object: {e}")
werkzeug.exceptions.BadRequest: 400 Bad Request: Failed to decode JSON object: Expecting ',' delimiter: line 2 column 17 (char 18)

2024-11-27 00:38:38 | ERROR | 400 Bad Request: Failed to decode JSON object: Expecting ',' delimiter: line 2 column 17 (char 18)
2024-11-27 00:38:38 | ERROR | Traceback (most recent call last):
  File "/home/angel/Documentos/repositorios/api_flask_ecommerce/.api_venv/lib/python3.11/site-packages/werkzeug/wrappers/request.py", line 611, in get_json
    rv = self.json_module.loads(data)
         ^^^^^^^^^^^^^^^^^^^^^^^^^^^^
  File "/home/angel/Documentos/repositorios/api_flask_ecommerce/.api_venv/lib/python3.11/site-packages/flask/json/provider.py", line 187, in loads
    return json.loads(s, **kwargs)
           ^^^^^^^^^^^^^^^^^^^^^^^
  File "/usr/lib/python3.11/json/__init__.py", line 346, in loads
    return _default_decoder.decode(s)
           ^^^^^^^^^^^^^^^^^^^^^^^^^^
  File "/usr/lib/python3.11/json/decoder.py", line 337, in decode
    obj, end = self.raw_decode(s, idx=_w(s, 0).end())
               ^^^^^^^^^^^^^^^^^^^^^^^^^^^^^^^^^^^^^^
  File "/usr/lib/python3.11/json/decoder.py", line 353, in raw_decode
    obj, end = self.scan_once(s, idx)
               ^^^^^^^^^^^^^^^^^^^^^^
json.decoder.JSONDecodeError: Expecting ',' delimiter: line 2 column 17 (char 18)

During handling of the above exception, another exception occurred:

Traceback (most recent call last):
  File "/home/angel/Documentos/repositorios/api_flask_ecommerce/src/routes/UsuariosRoutes.py", line 93, in eliminar_usuario
    if not request.json:
           ^^^^^^^^^^^^
  File "/home/angel/Documentos/repositorios/api_flask_ecommerce/.api_venv/lib/python3.11/site-packages/werkzeug/wrappers/request.py", line 560, in json
    return self.get_json()
           ^^^^^^^^^^^^^^^
  File "/home/angel/Documentos/repositorios/api_flask_ecommerce/.api_venv/lib/python3.11/site-packages/werkzeug/wrappers/request.py", line 620, in get_json
    rv = self.on_json_loading_failed(e)
         ^^^^^^^^^^^^^^^^^^^^^^^^^^^^^^
  File "/home/angel/Documentos/repositorios/api_flask_ecommerce/.api_venv/lib/python3.11/site-packages/flask/wrappers.py", line 214, in on_json_loading_failed
    return super().on_json_loading_failed(e)
           ^^^^^^^^^^^^^^^^^^^^^^^^^^^^^^^^^
  File "/home/angel/Documentos/repositorios/api_flask_ecommerce/.api_venv/lib/python3.11/site-packages/werkzeug/wrappers/request.py", line 645, in on_json_loading_failed
    raise BadRequest(f"Failed to decode JSON object: {e}")
werkzeug.exceptions.BadRequest: 400 Bad Request: Failed to decode JSON object: Expecting ',' delimiter: line 2 column 17 (char 18)

2024-11-27 00:41:24 | ERROR | 400 Bad Request: Failed to decode JSON object: Expecting ',' delimiter: line 2 column 17 (char 18)
2024-11-27 00:41:24 | ERROR | Traceback (most recent call last):
  File "/home/angel/Documentos/repositorios/api_flask_ecommerce/.api_venv/lib/python3.11/site-packages/werkzeug/wrappers/request.py", line 611, in get_json
    rv = self.json_module.loads(data)
         ^^^^^^^^^^^^^^^^^^^^^^^^^^^^
  File "/home/angel/Documentos/repositorios/api_flask_ecommerce/.api_venv/lib/python3.11/site-packages/flask/json/provider.py", line 187, in loads
    return json.loads(s, **kwargs)
           ^^^^^^^^^^^^^^^^^^^^^^^
  File "/usr/lib/python3.11/json/__init__.py", line 346, in loads
    return _default_decoder.decode(s)
           ^^^^^^^^^^^^^^^^^^^^^^^^^^
  File "/usr/lib/python3.11/json/decoder.py", line 337, in decode
    obj, end = self.raw_decode(s, idx=_w(s, 0).end())
               ^^^^^^^^^^^^^^^^^^^^^^^^^^^^^^^^^^^^^^
  File "/usr/lib/python3.11/json/decoder.py", line 353, in raw_decode
    obj, end = self.scan_once(s, idx)
               ^^^^^^^^^^^^^^^^^^^^^^
json.decoder.JSONDecodeError: Expecting ',' delimiter: line 2 column 17 (char 18)

During handling of the above exception, another exception occurred:

Traceback (most recent call last):
  File "/home/angel/Documentos/repositorios/api_flask_ecommerce/src/routes/UsuariosRoutes.py", line 93, in eliminar_usuario
    if not request.json:
           ^^^^^^^^^^^^
  File "/home/angel/Documentos/repositorios/api_flask_ecommerce/.api_venv/lib/python3.11/site-packages/werkzeug/wrappers/request.py", line 560, in json
    return self.get_json()
           ^^^^^^^^^^^^^^^
  File "/home/angel/Documentos/repositorios/api_flask_ecommerce/.api_venv/lib/python3.11/site-packages/werkzeug/wrappers/request.py", line 620, in get_json
    rv = self.on_json_loading_failed(e)
         ^^^^^^^^^^^^^^^^^^^^^^^^^^^^^^
  File "/home/angel/Documentos/repositorios/api_flask_ecommerce/.api_venv/lib/python3.11/site-packages/flask/wrappers.py", line 214, in on_json_loading_failed
    return super().on_json_loading_failed(e)
           ^^^^^^^^^^^^^^^^^^^^^^^^^^^^^^^^^
  File "/home/angel/Documentos/repositorios/api_flask_ecommerce/.api_venv/lib/python3.11/site-packages/werkzeug/wrappers/request.py", line 645, in on_json_loading_failed
    raise BadRequest(f"Failed to decode JSON object: {e}")
werkzeug.exceptions.BadRequest: 400 Bad Request: Failed to decode JSON object: Expecting ',' delimiter: line 2 column 17 (char 18)

2024-11-27 01:06:03 | ERROR | El procedimiento no insertó el usuario.
2024-11-27 01:06:03 | ERROR | Traceback (most recent call last):
  File "/home/angel/Documentos/repositorios/api_flask_ecommerce/src/services/UsuariosService.py", line 53, in agregar_usuario
    raise Exception("El procedimiento no insertó el usuario.")
Exception: El procedimiento no insertó el usuario.

2024-11-27 01:49:04 | ERROR | 'Usuarios' object has no attribute 'usuario_id'
2024-11-27 01:49:04 | ERROR | Traceback (most recent call last):
  File "/home/angel/Documentos/repositorios/api_flask_ecommerce/src/services/UsuariosService.py", line 75, in modificar_usuario
    user.usuario_id,
    ^^^^^^^^^^^^^^^
AttributeError: 'Usuarios' object has no attribute 'usuario_id'

2024-11-27 01:50:54 | ERROR | 'Usuarios' object has no attribute 'usuario_id'
2024-11-27 01:50:54 | ERROR | Traceback (most recent call last):
  File "/home/angel/Documentos/repositorios/api_flask_ecommerce/src/services/UsuariosService.py", line 75, in modificar_usuario
    user.usuario_id,
    ^^^^^^^^^^^^^^^
AttributeError: 'Usuarios' object has no attribute 'usuario_id'

2024-11-27 01:53:24 | ERROR | 'Usuarios' object has no attribute 'usuario_id'
2024-11-27 01:53:24 | ERROR | Traceback (most recent call last):
  File "/home/angel/Documentos/repositorios/api_flask_ecommerce/src/services/UsuariosService.py", line 75, in modificar_usuario
    user.usuario_id,
    ^^^^^^^^^^^^^^^
AttributeError: 'Usuarios' object has no attribute 'usuario_id'

2024-11-27 02:00:22 | ERROR | 'Usuarios' object has no attribute 'usuario_id'
2024-11-27 02:00:22 | ERROR | Traceback (most recent call last):
  File "/home/angel/Documentos/repositorios/api_flask_ecommerce/src/services/UsuariosService.py", line 75, in modificar_usuario
    user.usuario_id,
    ^^^^^^^^^^^^^^^
AttributeError: 'Usuarios' object has no attribute 'usuario_id'

2024-11-27 02:01:17 | ERROR | 'Usuarios' object has no attribute 'usuario_id'
2024-11-27 02:01:17 | ERROR | Traceback (most recent call last):
  File "/home/angel/Documentos/repositorios/api_flask_ecommerce/src/services/UsuariosService.py", line 75, in modificar_usuario
    user.usuario_id,
    ^^^^^^^^^^^^^^^
AttributeError: 'Usuarios' object has no attribute 'usuario_id'

2024-11-27 02:03:12 | ERROR | 'Usuarios' object has no attribute 'usuario_id'
2024-11-27 02:03:12 | ERROR | Traceback (most recent call last):
  File "/home/angel/Documentos/repositorios/api_flask_ecommerce/src/services/UsuariosService.py", line 75, in modificar_usuario
    user.usuario_id,
    ^^^^^^^^^^^^^^^
AttributeError: 'Usuarios' object has no attribute 'usuario_id'

2024-11-27 02:03:30 | ERROR | 'Usuarios' object has no attribute 'usuario_id'
2024-11-27 02:03:30 | ERROR | Traceback (most recent call last):
  File "/home/angel/Documentos/repositorios/api_flask_ecommerce/src/services/UsuariosService.py", line 75, in modificar_usuario
    user.usuario_id,
    ^^^^^^^^^^^^^^^
AttributeError: 'Usuarios' object has no attribute 'usuario_id'

2024-11-27 02:04:55 | ERROR | 'Usuarios' object has no attribute 'usuario_id'
2024-11-27 02:04:55 | ERROR | Traceback (most recent call last):
  File "/home/angel/Documentos/repositorios/api_flask_ecommerce/src/services/UsuariosService.py", line 75, in modificar_usuario
    user.usuario_id,
    ^^^^^^^^^^^^^^^
AttributeError: 'Usuarios' object has no attribute 'usuario_id'

2024-11-27 02:06:41 | ERROR | 'Usuarios' object has no attribute 'usuario_id'
2024-11-27 02:06:41 | ERROR | Traceback (most recent call last):
  File "/home/angel/Documentos/repositorios/api_flask_ecommerce/src/services/UsuariosService.py", line 76, in modificar_usuario
    user.usuario_id,
    ^^^^^^^^^^^^^^^
AttributeError: 'Usuarios' object has no attribute 'usuario_id'

2024-11-27 02:07:41 | ERROR | 'Usuarios' object has no attribute 'usuario_id'
2024-11-27 02:07:41 | ERROR | Traceback (most recent call last):
  File "/home/angel/Documentos/repositorios/api_flask_ecommerce/src/services/UsuariosService.py", line 76, in modificar_usuario
    user.usuario_id,
    ^^^^^^^^^^^^^^^
AttributeError: 'Usuarios' object has no attribute 'usuario_id'

2024-11-27 02:12:04 | ERROR | Invalid crypto padding
2024-11-27 02:12:04 | ERROR | Traceback (most recent call last):
  File "/home/angel/Documentos/repositorios/api_flask_ecommerce/.api_venv/lib/python3.11/site-packages/jwt/api_jws.py", line 282, in _load
    signature = base64url_decode(crypto_segment)
                ^^^^^^^^^^^^^^^^^^^^^^^^^^^^^^^^
  File "/home/angel/Documentos/repositorios/api_flask_ecommerce/.api_venv/lib/python3.11/site-packages/jwt/utils.py", line 33, in base64url_decode
    return base64.urlsafe_b64decode(input_bytes)
           ^^^^^^^^^^^^^^^^^^^^^^^^^^^^^^^^^^^^^
  File "/usr/lib/python3.11/base64.py", line 134, in urlsafe_b64decode
    return b64decode(s)
           ^^^^^^^^^^^^
  File "/usr/lib/python3.11/base64.py", line 88, in b64decode
    return binascii.a2b_base64(s, strict_mode=validate)
           ^^^^^^^^^^^^^^^^^^^^^^^^^^^^^^^^^^^^^^^^^^^^
binascii.Error: Incorrect padding

The above exception was the direct cause of the following exception:

Traceback (most recent call last):
  File "/home/angel/Documentos/repositorios/api_flask_ecommerce/src/utils/Security.py", line 47, in verify_token
    payload = jwt.decode(encoded_token, cls.secret, algorithms=["HS256"])
              ^^^^^^^^^^^^^^^^^^^^^^^^^^^^^^^^^^^^^^^^^^^^^^^^^^^^^^^^^^^
  File "/home/angel/Documentos/repositorios/api_flask_ecommerce/.api_venv/lib/python3.11/site-packages/jwt/api_jwt.py", line 211, in decode
    decoded = self.decode_complete(
              ^^^^^^^^^^^^^^^^^^^^^
  File "/home/angel/Documentos/repositorios/api_flask_ecommerce/.api_venv/lib/python3.11/site-packages/jwt/api_jwt.py", line 152, in decode_complete
    decoded = api_jws.decode_complete(
              ^^^^^^^^^^^^^^^^^^^^^^^^
  File "/home/angel/Documentos/repositorios/api_flask_ecommerce/.api_venv/lib/python3.11/site-packages/jwt/api_jws.py", line 199, in decode_complete
    payload, signing_input, header, signature = self._load(jwt)
                                                ^^^^^^^^^^^^^^^
  File "/home/angel/Documentos/repositorios/api_flask_ecommerce/.api_venv/lib/python3.11/site-packages/jwt/api_jws.py", line 284, in _load
    raise DecodeError("Invalid crypto padding") from err
jwt.exceptions.DecodeError: Invalid crypto padding

2024-11-27 02:22:08 | ERROR | 'Usuarios' object has no attribute 'usuario_id'
2024-11-27 02:22:08 | ERROR | Traceback (most recent call last):
  File "/home/angel/Documentos/repositorios/api_flask_ecommerce/src/services/UsuariosService.py", line 76, in modificar_usuario
    user.usuario_id,
    ^^^^^^^^^^^^^^^
AttributeError: 'Usuarios' object has no attribute 'usuario_id'

2024-11-27 02:23:42 | ERROR | Invalid crypto padding
2024-11-27 02:23:42 | ERROR | Traceback (most recent call last):
  File "/home/angel/Documentos/repositorios/api_flask_ecommerce/.api_venv/lib/python3.11/site-packages/jwt/api_jws.py", line 282, in _load
    signature = base64url_decode(crypto_segment)
                ^^^^^^^^^^^^^^^^^^^^^^^^^^^^^^^^
  File "/home/angel/Documentos/repositorios/api_flask_ecommerce/.api_venv/lib/python3.11/site-packages/jwt/utils.py", line 33, in base64url_decode
    return base64.urlsafe_b64decode(input_bytes)
           ^^^^^^^^^^^^^^^^^^^^^^^^^^^^^^^^^^^^^
  File "/usr/lib/python3.11/base64.py", line 134, in urlsafe_b64decode
    return b64decode(s)
           ^^^^^^^^^^^^
  File "/usr/lib/python3.11/base64.py", line 88, in b64decode
    return binascii.a2b_base64(s, strict_mode=validate)
           ^^^^^^^^^^^^^^^^^^^^^^^^^^^^^^^^^^^^^^^^^^^^
binascii.Error: Incorrect padding

The above exception was the direct cause of the following exception:

Traceback (most recent call last):
  File "/home/angel/Documentos/repositorios/api_flask_ecommerce/src/utils/Security.py", line 47, in verify_token
    payload = jwt.decode(encoded_token, cls.secret, algorithms=["HS256"])
              ^^^^^^^^^^^^^^^^^^^^^^^^^^^^^^^^^^^^^^^^^^^^^^^^^^^^^^^^^^^
  File "/home/angel/Documentos/repositorios/api_flask_ecommerce/.api_venv/lib/python3.11/site-packages/jwt/api_jwt.py", line 211, in decode
    decoded = self.decode_complete(
              ^^^^^^^^^^^^^^^^^^^^^
  File "/home/angel/Documentos/repositorios/api_flask_ecommerce/.api_venv/lib/python3.11/site-packages/jwt/api_jwt.py", line 152, in decode_complete
    decoded = api_jws.decode_complete(
              ^^^^^^^^^^^^^^^^^^^^^^^^
  File "/home/angel/Documentos/repositorios/api_flask_ecommerce/.api_venv/lib/python3.11/site-packages/jwt/api_jws.py", line 199, in decode_complete
    payload, signing_input, header, signature = self._load(jwt)
                                                ^^^^^^^^^^^^^^^
  File "/home/angel/Documentos/repositorios/api_flask_ecommerce/.api_venv/lib/python3.11/site-packages/jwt/api_jws.py", line 284, in _load
    raise DecodeError("Invalid crypto padding") from err
jwt.exceptions.DecodeError: Invalid crypto padding

