2024-11-26 23:03:15 | ERROR | El procedimiento no insertó el usuario.
2024-11-26 23:03:15 | ERROR | Traceback (most recent call last):
  File "/home/angel/Documentos/repositorios/api_flask_ecommerce/src/services/UsuariosService.py", line 50, in agregar_usuario
    raise Exception("El procedimiento no insertó el usuario.")
Exception: El procedimiento no insertó el usuario.

2024-11-26 23:11:31 | ERROR | El procedimiento no insertó el usuario.
2024-11-26 23:11:31 | ERROR | Traceback (most recent call last):
  File "/home/angel/Documentos/repositorios/api_flask_ecommerce/src/services/UsuariosService.py", line 51, in agregar_usuario
    raise Exception("El procedimiento no insertó el usuario.")
Exception: El procedimiento no insertó el usuario.

2024-11-26 23:14:03 | ERROR | El procedimiento no insertó el usuario.
2024-11-26 23:14:03 | ERROR | Traceback (most recent call last):
  File "/home/angel/Documentos/repositorios/api_flask_ecommerce/src/services/UsuariosService.py", line 51, in agregar_usuario
    raise Exception("El procedimiento no insertó el usuario.")
Exception: El procedimiento no insertó el usuario.

2024-11-26 23:14:44 | ERROR | El procedimiento no insertó el usuario.
2024-11-26 23:14:44 | ERROR | Traceback (most recent call last):
  File "/home/angel/Documentos/repositorios/api_flask_ecommerce/src/services/UsuariosService.py", line 51, in agregar_usuario
    raise Exception("El procedimiento no insertó el usuario.")
Exception: El procedimiento no insertó el usuario.

2024-11-26 23:25:15 | ERROR | 'NoneType' object has no attribute 'cursor'
2024-11-26 23:25:15 | ERROR | Traceback (most recent call last):
  File "/home/angel/Documentos/repositorios/api_flask_ecommerce/src/services/AuthService.py", line 18, in login_user
    with connection.cursor() as cursor:
         ^^^^^^^^^^^^^^^^^
AttributeError: 'NoneType' object has no attribute 'cursor'

2024-11-26 23:25:22 | ERROR | 'NoneType' object has no attribute 'cursor'
2024-11-26 23:25:22 | ERROR | Traceback (most recent call last):
  File "/home/angel/Documentos/repositorios/api_flask_ecommerce/src/services/AuthService.py", line 18, in login_user
    with connection.cursor() as cursor:
         ^^^^^^^^^^^^^^^^^
AttributeError: 'NoneType' object has no attribute 'cursor'

2024-11-26 23:25:46 | ERROR | 'NoneType' object has no attribute 'cursor'
2024-11-26 23:25:46 | ERROR | Traceback (most recent call last):
  File "/home/angel/Documentos/repositorios/api_flask_ecommerce/src/services/AuthService.py", line 18, in login_user
    with connection.cursor() as cursor:
         ^^^^^^^^^^^^^^^^^
AttributeError: 'NoneType' object has no attribute 'cursor'

2024-11-26 23:26:21 | ERROR | 'NoneType' object has no attribute 'cursor'
2024-11-26 23:26:21 | ERROR | Traceback (most recent call last):
  File "/home/angel/Documentos/repositorios/api_flask_ecommerce/src/services/AuthService.py", line 18, in login_user
    with connection.cursor() as cursor:
         ^^^^^^^^^^^^^^^^^
AttributeError: 'NoneType' object has no attribute 'cursor'

2024-11-26 23:26:50 | ERROR | 'NoneType' object has no attribute 'cursor'
2024-11-26 23:26:50 | ERROR | Traceback (most recent call last):
  File "/home/angel/Documentos/repositorios/api_flask_ecommerce/src/services/AuthService.py", line 18, in login_user
    with connection.cursor() as cursor:
         ^^^^^^^^^^^^^^^^^
AttributeError: 'NoneType' object has no attribute 'cursor'

2024-11-26 23:29:41 | ERROR | El procedimiento no insertó el usuario.
2024-11-26 23:29:41 | ERROR | Traceback (most recent call last):
  File "/home/angel/Documentos/repositorios/api_flask_ecommerce/src/services/UsuariosService.py", line 51, in agregar_usuario
    raise Exception("El procedimiento no insertó el usuario.")
Exception: El procedimiento no insertó el usuario.

2024-11-26 23:39:00 | ERROR | El procedimiento no insertó el usuario.
2024-11-26 23:39:00 | ERROR | Traceback (most recent call last):
  File "/home/angel/Documentos/repositorios/api_flask_ecommerce/src/services/UsuariosService.py", line 52, in agregar_usuario
    raise Exception("El procedimiento no insertó el usuario.")
Exception: El procedimiento no insertó el usuario.

2024-11-26 23:42:12 | ERROR | El procedimiento no insertó el usuario.
2024-11-26 23:42:12 | ERROR | Traceback (most recent call last):
  File "/home/angel/Documentos/repositorios/api_flask_ecommerce/src/services/UsuariosService.py", line 52, in agregar_usuario
    raise Exception("El procedimiento no insertó el usuario.")
Exception: El procedimiento no insertó el usuario.

2024-11-27 00:04:54 | ERROR | El procedimiento no insertó el usuario.
2024-11-27 00:04:54 | ERROR | Traceback (most recent call last):
  File "/home/angel/Documentos/repositorios/api_flask_ecommerce/src/services/UsuariosService.py", line 52, in agregar_usuario
    raise Exception("El procedimiento no insertó el usuario.")
Exception: El procedimiento no insertó el usuario.

2024-11-27 00:07:04 | ERROR | El procedimiento no insertó el usuario.
2024-11-27 00:07:04 | ERROR | Traceback (most recent call last):
  File "/home/angel/Documentos/repositorios/api_flask_ecommerce/src/services/UsuariosService.py", line 52, in agregar_usuario
    raise Exception("El procedimiento no insertó el usuario.")
Exception: El procedimiento no insertó el usuario.

2024-11-27 00:10:26 | ERROR | El procedimiento no insertó el usuario.
2024-11-27 00:10:26 | ERROR | Traceback (most recent call last):
  File "/home/angel/Documentos/repositorios/api_flask_ecommerce/src/services/UsuariosService.py", line 52, in agregar_usuario
    raise Exception("El procedimiento no insertó el usuario.")
Exception: El procedimiento no insertó el usuario.

2024-11-27 00:12:54 | ERROR | not enough arguments for format string
2024-11-27 00:12:54 | ERROR | Traceback (most recent call last):
  File "/home/angel/Documentos/repositorios/api_flask_ecommerce/src/services/UsuariosService.py", line 47, in agregar_usuario
    cursor.callproc('call agregar_usuario(%s, %s, %s, %s)',
  File "/home/angel/Documentos/repositorios/api_flask_ecommerce/.api_venv/lib/python3.11/site-packages/pymysql/cursors.py", line 259, in callproc
    % ",".join(
      ^^^^^^^^^
  File "/home/angel/Documentos/repositorios/api_flask_ecommerce/.api_venv/lib/python3.11/site-packages/pymysql/cursors.py", line 260, in <genexpr>
    fmt % (index, conn.escape(arg)) for index, arg in enumerate(args)
    ~~~~^~~~~~~~~~~~~~~~~~~~~~~~~~~
TypeError: not enough arguments for format string

2024-11-27 00:17:03 | ERROR | El procedimiento no insertó el usuario.
2024-11-27 00:17:03 | ERROR | Traceback (most recent call last):
  File "/home/angel/Documentos/repositorios/api_flask_ecommerce/src/services/UsuariosService.py", line 51, in agregar_usuario
    raise Exception("El procedimiento no insertó el usuario.")
Exception: El procedimiento no insertó el usuario.

2024-11-27 00:30:24 | ERROR | El procedimiento no insertó el usuario.
2024-11-27 00:30:24 | ERROR | Traceback (most recent call last):
  File "/home/angel/Documentos/repositorios/api_flask_ecommerce/src/services/UsuariosService.py", line 51, in agregar_usuario
    raise Exception("El procedimiento no insertó el usuario.")
Exception: El procedimiento no insertó el usuario.

2024-11-27 00:34:17 | ERROR | 400 Bad Request: Failed to decode JSON object: Expecting ',' delimiter: line 2 column 17 (char 18)
2024-11-27 00:34:17 | ERROR | Traceback (most recent call last):
  File "/home/angel/Documentos/repositorios/api_flask_ecommerce/.api_venv/lib/python3.11/site-packages/werkzeug/wrappers/request.py", line 611, in get_json
    rv = self.json_module.loads(data)
         ^^^^^^^^^^^^^^^^^^^^^^^^^^^^
  File "/home/angel/Documentos/repositorios/api_flask_ecommerce/.api_venv/lib/python3.11/site-packages/flask/json/provider.py", line 187, in loads
    return json.loads(s, **kwargs)
           ^^^^^^^^^^^^^^^^^^^^^^^
  File "/usr/lib/python3.11/json/__init__.py", line 346, in loads
    return _default_decoder.decode(s)
           ^^^^^^^^^^^^^^^^^^^^^^^^^^
  File "/usr/lib/python3.11/json/decoder.py", line 337, in decode
    obj, end = self.raw_decode(s, idx=_w(s, 0).end())
               ^^^^^^^^^^^^^^^^^^^^^^^^^^^^^^^^^^^^^^
  File "/usr/lib/python3.11/json/decoder.py", line 353, in raw_decode
    obj, end = self.scan_once(s, idx)
               ^^^^^^^^^^^^^^^^^^^^^^
json.decoder.JSONDecodeError: Expecting ',' delimiter: line 2 column 17 (char 18)

During handling of the above exception, another exception occurred:

Traceback (most recent call last):
  File "/home/angel/Documentos/repositorios/api_flask_ecommerce/src/routes/UsuariosRoutes.py", line 93, in eliminar_usuario
    if not request.json:
           ^^^^^^^^^^^^
  File "/home/angel/Documentos/repositorios/api_flask_ecommerce/.api_venv/lib/python3.11/site-packages/werkzeug/wrappers/request.py", line 560, in json
    return self.get_json()
           ^^^^^^^^^^^^^^^
  File "/home/angel/Documentos/repositorios/api_flask_ecommerce/.api_venv/lib/python3.11/site-packages/werkzeug/wrappers/request.py", line 620, in get_json
    rv = self.on_json_loading_failed(e)
         ^^^^^^^^^^^^^^^^^^^^^^^^^^^^^^
  File "/home/angel/Documentos/repositorios/api_flask_ecommerce/.api_venv/lib/python3.11/site-packages/flask/wrappers.py", line 214, in on_json_loading_failed
    return super().on_json_loading_failed(e)
           ^^^^^^^^^^^^^^^^^^^^^^^^^^^^^^^^^
  File "/home/angel/Documentos/repositorios/api_flask_ecommerce/.api_venv/lib/python3.11/site-packages/werkzeug/wrappers/request.py", line 645, in on_json_loading_failed
    raise BadRequest(f"Failed to decode JSON object: {e}")
werkzeug.exceptions.BadRequest: 400 Bad Request: Failed to decode JSON object: Expecting ',' delimiter: line 2 column 17 (char 18)

2024-11-27 00:35:47 | ERROR | El procedimiento no insertó el usuario.
2024-11-27 00:35:47 | ERROR | Traceback (most recent call last):
  File "/home/angel/Documentos/repositorios/api_flask_ecommerce/src/services/UsuariosService.py", line 51, in agregar_usuario
    raise Exception("El procedimiento no insertó el usuario.")
Exception: El procedimiento no insertó el usuario.

2024-11-27 00:37:48 | ERROR | 400 Bad Request: Failed to decode JSON object: Expecting ',' delimiter: line 2 column 17 (char 18)
2024-11-27 00:37:48 | ERROR | Traceback (most recent call last):
  File "/home/angel/Documentos/repositorios/api_flask_ecommerce/.api_venv/lib/python3.11/site-packages/werkzeug/wrappers/request.py", line 611, in get_json
    rv = self.json_module.loads(data)
         ^^^^^^^^^^^^^^^^^^^^^^^^^^^^
  File "/home/angel/Documentos/repositorios/api_flask_ecommerce/.api_venv/lib/python3.11/site-packages/flask/json/provider.py", line 187, in loads
    return json.loads(s, **kwargs)
           ^^^^^^^^^^^^^^^^^^^^^^^
  File "/usr/lib/python3.11/json/__init__.py", line 346, in loads
    return _default_decoder.decode(s)
           ^^^^^^^^^^^^^^^^^^^^^^^^^^
  File "/usr/lib/python3.11/json/decoder.py", line 337, in decode
    obj, end = self.raw_decode(s, idx=_w(s, 0).end())
               ^^^^^^^^^^^^^^^^^^^^^^^^^^^^^^^^^^^^^^
  File "/usr/lib/python3.11/json/decoder.py", line 353, in raw_decode
    obj, end = self.scan_once(s, idx)
               ^^^^^^^^^^^^^^^^^^^^^^
json.decoder.JSONDecodeError: Expecting ',' delimiter: line 2 column 17 (char 18)

During handling of the above exception, another exception occurred:

Traceback (most recent call last):
  File "/home/angel/Documentos/repositorios/api_flask_ecommerce/src/routes/UsuariosRoutes.py", line 93, in eliminar_usuario
    if not request.json:
           ^^^^^^^^^^^^
  File "/home/angel/Documentos/repositorios/api_flask_ecommerce/.api_venv/lib/python3.11/site-packages/werkzeug/wrappers/request.py", line 560, in json
    return self.get_json()
           ^^^^^^^^^^^^^^^
  File "/home/angel/Documentos/repositorios/api_flask_ecommerce/.api_venv/lib/python3.11/site-packages/werkzeug/wrappers/request.py", line 620, in get_json
    rv = self.on_json_loading_failed(e)
         ^^^^^^^^^^^^^^^^^^^^^^^^^^^^^^
  File "/home/angel/Documentos/repositorios/api_flask_ecommerce/.api_venv/lib/python3.11/site-packages/flask/wrappers.py", line 214, in on_json_loading_failed
    return super().on_json_loading_failed(e)
           ^^^^^^^^^^^^^^^^^^^^^^^^^^^^^^^^^
  File "/home/angel/Documentos/repositorios/api_flask_ecommerce/.api_venv/lib/python3.11/site-packages/werkzeug/wrappers/request.py", line 645, in on_json_loading_failed
    raise BadRequest(f"Failed to decode JSON object: {e}")
werkzeug.exceptions.BadRequest: 400 Bad Request: Failed to decode JSON object: Expecting ',' delimiter: line 2 column 17 (char 18)

2024-11-27 00:38:38 | ERROR | 400 Bad Request: Failed to decode JSON object: Expecting ',' delimiter: line 2 column 17 (char 18)
2024-11-27 00:38:38 | ERROR | Traceback (most recent call last):
  File "/home/angel/Documentos/repositorios/api_flask_ecommerce/.api_venv/lib/python3.11/site-packages/werkzeug/wrappers/request.py", line 611, in get_json
    rv = self.json_module.loads(data)
         ^^^^^^^^^^^^^^^^^^^^^^^^^^^^
  File "/home/angel/Documentos/repositorios/api_flask_ecommerce/.api_venv/lib/python3.11/site-packages/flask/json/provider.py", line 187, in loads
    return json.loads(s, **kwargs)
           ^^^^^^^^^^^^^^^^^^^^^^^
  File "/usr/lib/python3.11/json/__init__.py", line 346, in loads
    return _default_decoder.decode(s)
           ^^^^^^^^^^^^^^^^^^^^^^^^^^
  File "/usr/lib/python3.11/json/decoder.py", line 337, in decode
    obj, end = self.raw_decode(s, idx=_w(s, 0).end())
               ^^^^^^^^^^^^^^^^^^^^^^^^^^^^^^^^^^^^^^
  File "/usr/lib/python3.11/json/decoder.py", line 353, in raw_decode
    obj, end = self.scan_once(s, idx)
               ^^^^^^^^^^^^^^^^^^^^^^
json.decoder.JSONDecodeError: Expecting ',' delimiter: line 2 column 17 (char 18)

During handling of the above exception, another exception occurred:

Traceback (most recent call last):
  File "/home/angel/Documentos/repositorios/api_flask_ecommerce/src/routes/UsuariosRoutes.py", line 93, in eliminar_usuario
    if not request.json:
           ^^^^^^^^^^^^
  File "/home/angel/Documentos/repositorios/api_flask_ecommerce/.api_venv/lib/python3.11/site-packages/werkzeug/wrappers/request.py", line 560, in json
    return self.get_json()
           ^^^^^^^^^^^^^^^
  File "/home/angel/Documentos/repositorios/api_flask_ecommerce/.api_venv/lib/python3.11/site-packages/werkzeug/wrappers/request.py", line 620, in get_json
    rv = self.on_json_loading_failed(e)
         ^^^^^^^^^^^^^^^^^^^^^^^^^^^^^^
  File "/home/angel/Documentos/repositorios/api_flask_ecommerce/.api_venv/lib/python3.11/site-packages/flask/wrappers.py", line 214, in on_json_loading_failed
    return super().on_json_loading_failed(e)
           ^^^^^^^^^^^^^^^^^^^^^^^^^^^^^^^^^
  File "/home/angel/Documentos/repositorios/api_flask_ecommerce/.api_venv/lib/python3.11/site-packages/werkzeug/wrappers/request.py", line 645, in on_json_loading_failed
    raise BadRequest(f"Failed to decode JSON object: {e}")
werkzeug.exceptions.BadRequest: 400 Bad Request: Failed to decode JSON object: Expecting ',' delimiter: line 2 column 17 (char 18)

2024-11-27 00:41:24 | ERROR | 400 Bad Request: Failed to decode JSON object: Expecting ',' delimiter: line 2 column 17 (char 18)
2024-11-27 00:41:24 | ERROR | Traceback (most recent call last):
  File "/home/angel/Documentos/repositorios/api_flask_ecommerce/.api_venv/lib/python3.11/site-packages/werkzeug/wrappers/request.py", line 611, in get_json
    rv = self.json_module.loads(data)
         ^^^^^^^^^^^^^^^^^^^^^^^^^^^^
  File "/home/angel/Documentos/repositorios/api_flask_ecommerce/.api_venv/lib/python3.11/site-packages/flask/json/provider.py", line 187, in loads
    return json.loads(s, **kwargs)
           ^^^^^^^^^^^^^^^^^^^^^^^
  File "/usr/lib/python3.11/json/__init__.py", line 346, in loads
    return _default_decoder.decode(s)
           ^^^^^^^^^^^^^^^^^^^^^^^^^^
  File "/usr/lib/python3.11/json/decoder.py", line 337, in decode
    obj, end = self.raw_decode(s, idx=_w(s, 0).end())
               ^^^^^^^^^^^^^^^^^^^^^^^^^^^^^^^^^^^^^^
  File "/usr/lib/python3.11/json/decoder.py", line 353, in raw_decode
    obj, end = self.scan_once(s, idx)
               ^^^^^^^^^^^^^^^^^^^^^^
json.decoder.JSONDecodeError: Expecting ',' delimiter: line 2 column 17 (char 18)

During handling of the above exception, another exception occurred:

Traceback (most recent call last):
  File "/home/angel/Documentos/repositorios/api_flask_ecommerce/src/routes/UsuariosRoutes.py", line 93, in eliminar_usuario
    if not request.json:
           ^^^^^^^^^^^^
  File "/home/angel/Documentos/repositorios/api_flask_ecommerce/.api_venv/lib/python3.11/site-packages/werkzeug/wrappers/request.py", line 560, in json
    return self.get_json()
           ^^^^^^^^^^^^^^^
  File "/home/angel/Documentos/repositorios/api_flask_ecommerce/.api_venv/lib/python3.11/site-packages/werkzeug/wrappers/request.py", line 620, in get_json
    rv = self.on_json_loading_failed(e)
         ^^^^^^^^^^^^^^^^^^^^^^^^^^^^^^
  File "/home/angel/Documentos/repositorios/api_flask_ecommerce/.api_venv/lib/python3.11/site-packages/flask/wrappers.py", line 214, in on_json_loading_failed
    return super().on_json_loading_failed(e)
           ^^^^^^^^^^^^^^^^^^^^^^^^^^^^^^^^^
  File "/home/angel/Documentos/repositorios/api_flask_ecommerce/.api_venv/lib/python3.11/site-packages/werkzeug/wrappers/request.py", line 645, in on_json_loading_failed
    raise BadRequest(f"Failed to decode JSON object: {e}")
werkzeug.exceptions.BadRequest: 400 Bad Request: Failed to decode JSON object: Expecting ',' delimiter: line 2 column 17 (char 18)

2024-11-27 01:06:03 | ERROR | El procedimiento no insertó el usuario.
2024-11-27 01:06:03 | ERROR | Traceback (most recent call last):
  File "/home/angel/Documentos/repositorios/api_flask_ecommerce/src/services/UsuariosService.py", line 53, in agregar_usuario
    raise Exception("El procedimiento no insertó el usuario.")
Exception: El procedimiento no insertó el usuario.

2024-11-27 01:49:04 | ERROR | 'Usuarios' object has no attribute 'usuario_id'
2024-11-27 01:49:04 | ERROR | Traceback (most recent call last):
  File "/home/angel/Documentos/repositorios/api_flask_ecommerce/src/services/UsuariosService.py", line 75, in modificar_usuario
    user.usuario_id,
    ^^^^^^^^^^^^^^^
AttributeError: 'Usuarios' object has no attribute 'usuario_id'

2024-11-27 01:50:54 | ERROR | 'Usuarios' object has no attribute 'usuario_id'
2024-11-27 01:50:54 | ERROR | Traceback (most recent call last):
  File "/home/angel/Documentos/repositorios/api_flask_ecommerce/src/services/UsuariosService.py", line 75, in modificar_usuario
    user.usuario_id,
    ^^^^^^^^^^^^^^^
AttributeError: 'Usuarios' object has no attribute 'usuario_id'

2024-11-27 01:53:24 | ERROR | 'Usuarios' object has no attribute 'usuario_id'
2024-11-27 01:53:24 | ERROR | Traceback (most recent call last):
  File "/home/angel/Documentos/repositorios/api_flask_ecommerce/src/services/UsuariosService.py", line 75, in modificar_usuario
    user.usuario_id,
    ^^^^^^^^^^^^^^^
AttributeError: 'Usuarios' object has no attribute 'usuario_id'

2024-11-27 02:00:22 | ERROR | 'Usuarios' object has no attribute 'usuario_id'
2024-11-27 02:00:22 | ERROR | Traceback (most recent call last):
  File "/home/angel/Documentos/repositorios/api_flask_ecommerce/src/services/UsuariosService.py", line 75, in modificar_usuario
    user.usuario_id,
    ^^^^^^^^^^^^^^^
AttributeError: 'Usuarios' object has no attribute 'usuario_id'

2024-11-27 02:01:17 | ERROR | 'Usuarios' object has no attribute 'usuario_id'
2024-11-27 02:01:17 | ERROR | Traceback (most recent call last):
  File "/home/angel/Documentos/repositorios/api_flask_ecommerce/src/services/UsuariosService.py", line 75, in modificar_usuario
    user.usuario_id,
    ^^^^^^^^^^^^^^^
AttributeError: 'Usuarios' object has no attribute 'usuario_id'

2024-11-27 02:03:12 | ERROR | 'Usuarios' object has no attribute 'usuario_id'
2024-11-27 02:03:12 | ERROR | Traceback (most recent call last):
  File "/home/angel/Documentos/repositorios/api_flask_ecommerce/src/services/UsuariosService.py", line 75, in modificar_usuario
    user.usuario_id,
    ^^^^^^^^^^^^^^^
AttributeError: 'Usuarios' object has no attribute 'usuario_id'

2024-11-27 02:03:30 | ERROR | 'Usuarios' object has no attribute 'usuario_id'
2024-11-27 02:03:30 | ERROR | Traceback (most recent call last):
  File "/home/angel/Documentos/repositorios/api_flask_ecommerce/src/services/UsuariosService.py", line 75, in modificar_usuario
    user.usuario_id,
    ^^^^^^^^^^^^^^^
AttributeError: 'Usuarios' object has no attribute 'usuario_id'

2024-11-27 02:04:55 | ERROR | 'Usuarios' object has no attribute 'usuario_id'
2024-11-27 02:04:55 | ERROR | Traceback (most recent call last):
  File "/home/angel/Documentos/repositorios/api_flask_ecommerce/src/services/UsuariosService.py", line 75, in modificar_usuario
    user.usuario_id,
    ^^^^^^^^^^^^^^^
AttributeError: 'Usuarios' object has no attribute 'usuario_id'

2024-11-27 02:06:41 | ERROR | 'Usuarios' object has no attribute 'usuario_id'
2024-11-27 02:06:41 | ERROR | Traceback (most recent call last):
  File "/home/angel/Documentos/repositorios/api_flask_ecommerce/src/services/UsuariosService.py", line 76, in modificar_usuario
    user.usuario_id,
    ^^^^^^^^^^^^^^^
AttributeError: 'Usuarios' object has no attribute 'usuario_id'

2024-11-27 02:07:41 | ERROR | 'Usuarios' object has no attribute 'usuario_id'
2024-11-27 02:07:41 | ERROR | Traceback (most recent call last):
  File "/home/angel/Documentos/repositorios/api_flask_ecommerce/src/services/UsuariosService.py", line 76, in modificar_usuario
    user.usuario_id,
    ^^^^^^^^^^^^^^^
AttributeError: 'Usuarios' object has no attribute 'usuario_id'

2024-11-27 02:12:04 | ERROR | Invalid crypto padding
2024-11-27 02:12:04 | ERROR | Traceback (most recent call last):
  File "/home/angel/Documentos/repositorios/api_flask_ecommerce/.api_venv/lib/python3.11/site-packages/jwt/api_jws.py", line 282, in _load
    signature = base64url_decode(crypto_segment)
                ^^^^^^^^^^^^^^^^^^^^^^^^^^^^^^^^
  File "/home/angel/Documentos/repositorios/api_flask_ecommerce/.api_venv/lib/python3.11/site-packages/jwt/utils.py", line 33, in base64url_decode
    return base64.urlsafe_b64decode(input_bytes)
           ^^^^^^^^^^^^^^^^^^^^^^^^^^^^^^^^^^^^^
  File "/usr/lib/python3.11/base64.py", line 134, in urlsafe_b64decode
    return b64decode(s)
           ^^^^^^^^^^^^
  File "/usr/lib/python3.11/base64.py", line 88, in b64decode
    return binascii.a2b_base64(s, strict_mode=validate)
           ^^^^^^^^^^^^^^^^^^^^^^^^^^^^^^^^^^^^^^^^^^^^
binascii.Error: Incorrect padding

The above exception was the direct cause of the following exception:

Traceback (most recent call last):
  File "/home/angel/Documentos/repositorios/api_flask_ecommerce/src/utils/Security.py", line 47, in verify_token
    payload = jwt.decode(encoded_token, cls.secret, algorithms=["HS256"])
              ^^^^^^^^^^^^^^^^^^^^^^^^^^^^^^^^^^^^^^^^^^^^^^^^^^^^^^^^^^^
  File "/home/angel/Documentos/repositorios/api_flask_ecommerce/.api_venv/lib/python3.11/site-packages/jwt/api_jwt.py", line 211, in decode
    decoded = self.decode_complete(
              ^^^^^^^^^^^^^^^^^^^^^
  File "/home/angel/Documentos/repositorios/api_flask_ecommerce/.api_venv/lib/python3.11/site-packages/jwt/api_jwt.py", line 152, in decode_complete
    decoded = api_jws.decode_complete(
              ^^^^^^^^^^^^^^^^^^^^^^^^
  File "/home/angel/Documentos/repositorios/api_flask_ecommerce/.api_venv/lib/python3.11/site-packages/jwt/api_jws.py", line 199, in decode_complete
    payload, signing_input, header, signature = self._load(jwt)
                                                ^^^^^^^^^^^^^^^
  File "/home/angel/Documentos/repositorios/api_flask_ecommerce/.api_venv/lib/python3.11/site-packages/jwt/api_jws.py", line 284, in _load
    raise DecodeError("Invalid crypto padding") from err
jwt.exceptions.DecodeError: Invalid crypto padding

2024-11-27 02:22:08 | ERROR | 'Usuarios' object has no attribute 'usuario_id'
2024-11-27 02:22:08 | ERROR | Traceback (most recent call last):
  File "/home/angel/Documentos/repositorios/api_flask_ecommerce/src/services/UsuariosService.py", line 76, in modificar_usuario
    user.usuario_id,
    ^^^^^^^^^^^^^^^
AttributeError: 'Usuarios' object has no attribute 'usuario_id'

2024-11-27 02:23:42 | ERROR | Invalid crypto padding
2024-11-27 02:23:42 | ERROR | Traceback (most recent call last):
  File "/home/angel/Documentos/repositorios/api_flask_ecommerce/.api_venv/lib/python3.11/site-packages/jwt/api_jws.py", line 282, in _load
    signature = base64url_decode(crypto_segment)
                ^^^^^^^^^^^^^^^^^^^^^^^^^^^^^^^^
  File "/home/angel/Documentos/repositorios/api_flask_ecommerce/.api_venv/lib/python3.11/site-packages/jwt/utils.py", line 33, in base64url_decode
    return base64.urlsafe_b64decode(input_bytes)
           ^^^^^^^^^^^^^^^^^^^^^^^^^^^^^^^^^^^^^
  File "/usr/lib/python3.11/base64.py", line 134, in urlsafe_b64decode
    return b64decode(s)
           ^^^^^^^^^^^^
  File "/usr/lib/python3.11/base64.py", line 88, in b64decode
    return binascii.a2b_base64(s, strict_mode=validate)
           ^^^^^^^^^^^^^^^^^^^^^^^^^^^^^^^^^^^^^^^^^^^^
binascii.Error: Incorrect padding

The above exception was the direct cause of the following exception:

Traceback (most recent call last):
  File "/home/angel/Documentos/repositorios/api_flask_ecommerce/src/utils/Security.py", line 47, in verify_token
    payload = jwt.decode(encoded_token, cls.secret, algorithms=["HS256"])
              ^^^^^^^^^^^^^^^^^^^^^^^^^^^^^^^^^^^^^^^^^^^^^^^^^^^^^^^^^^^
  File "/home/angel/Documentos/repositorios/api_flask_ecommerce/.api_venv/lib/python3.11/site-packages/jwt/api_jwt.py", line 211, in decode
    decoded = self.decode_complete(
              ^^^^^^^^^^^^^^^^^^^^^
  File "/home/angel/Documentos/repositorios/api_flask_ecommerce/.api_venv/lib/python3.11/site-packages/jwt/api_jwt.py", line 152, in decode_complete
    decoded = api_jws.decode_complete(
              ^^^^^^^^^^^^^^^^^^^^^^^^
  File "/home/angel/Documentos/repositorios/api_flask_ecommerce/.api_venv/lib/python3.11/site-packages/jwt/api_jws.py", line 199, in decode_complete
    payload, signing_input, header, signature = self._load(jwt)
                                                ^^^^^^^^^^^^^^^
  File "/home/angel/Documentos/repositorios/api_flask_ecommerce/.api_venv/lib/python3.11/site-packages/jwt/api_jws.py", line 284, in _load
    raise DecodeError("Invalid crypto padding") from err
jwt.exceptions.DecodeError: Invalid crypto padding

2024-11-27 19:57:54 | ERROR | 'Usuarios' object has no attribute 'usuario_id'
2024-11-27 19:57:54 | ERROR | Traceback (most recent call last):
  File "/home/angel/Documentos/repositorios/api_flask_ecommerce/src/services/UsuariosService.py", line 76, in modificar_usuario
    user.usuario_id,
    ^^^^^^^^^^^^^^^
AttributeError: 'Usuarios' object has no attribute 'usuario_id'

2024-11-27 20:02:50 | ERROR | 'Usuarios' object has no attribute 'usuario_id'
2024-11-27 20:02:50 | ERROR | Traceback (most recent call last):
  File "/home/angel/Documentos/repositorios/api_flask_ecommerce/src/services/UsuariosService.py", line 76, in modificar_usuario
    user.usuario_id,
    ^^^^^^^^^^^^^^^
AttributeError: 'Usuarios' object has no attribute 'usuario_id'

2024-11-28 00:11:19 | ERROR | 'Usuarios' object has no attribute 'usuario_id'
2024-11-28 00:11:19 | ERROR | Traceback (most recent call last):
  File "/home/angel/Documentos/repositorios/api_flask_ecommerce/src/services/UsuariosService.py", line 76, in modificar_usuario
    user.usuario_id,
    ^^^^^^^^^^^^^^^
AttributeError: 'Usuarios' object has no attribute 'usuario_id'

2024-11-28 00:30:32 | ERROR | 'Usuarios' object has no attribute 'id'
2024-11-28 00:30:32 | ERROR | Traceback (most recent call last):
  File "/home/angel/Documentos/repositorios/api_flask_ecommerce/src/routes/UsuariosRoutes.py", line 112, in modificar_usuario
    print("Usuario a modificar:", _user.to_json())
                                  ^^^^^^^^^^^^^^^
  File "/home/angel/Documentos/repositorios/api_flask_ecommerce/src/models/UsuariosModel.py", line 12, in to_json
    'usuario_id':self.id,
                 ^^^^^^^
AttributeError: 'Usuarios' object has no attribute 'id'

2024-11-28 02:06:22 | ERROR | type object 'UsuariosService' has no attribute 'consultar_usuario_por_id'
2024-11-28 02:06:22 | ERROR | Traceback (most recent call last):
  File "/home/angel/Documentos/repositorios/api_flask_ecommerce/src/routes/UsuariosRoutes.py", line 59, in consultar_usuario
    usuario = UsuariosService.consultar_usuario_por_id(usuario_id)
              ^^^^^^^^^^^^^^^^^^^^^^^^^^^^^^^^^^^^^^^^
AttributeError: type object 'UsuariosService' has no attribute 'consultar_usuario_por_id'

2024-11-28 02:44:18 | ERROR | type object 'UsuariosService' has no attribute 'consultar_usuario_por_id'
2024-11-28 02:44:18 | ERROR | Traceback (most recent call last):
  File "/home/angel/Documentos/repositorios/api_flask_ecommerce/src/routes/UsuariosRoutes.py", line 59, in consultar_usuario
    usuario = UsuariosService.consultar_usuario_por_id(usuario_id)
              ^^^^^^^^^^^^^^^^^^^^^^^^^^^^^^^^^^^^^^^^
AttributeError: type object 'UsuariosService' has no attribute 'consultar_usuario_por_id'

2024-11-28 02:54:27 | ERROR | El procedimiento no insertó el usuario.
2024-11-28 02:54:27 | ERROR | Traceback (most recent call last):
  File "/home/angel/Documentos/repositorios/api_flask_ecommerce/src/services/UsuariosService.py", line 93, in agregar_usuario
    raise Exception("El procedimiento no insertó el usuario.")
Exception: El procedimiento no insertó el usuario.

2024-11-28 02:59:09 | ERROR | El procedimiento no insertó el usuario.
2024-11-28 02:59:09 | ERROR | Traceback (most recent call last):
  File "/home/angel/Documentos/repositorios/api_flask_ecommerce/src/services/UsuariosService.py", line 93, in agregar_usuario
    raise Exception("El procedimiento no insertó el usuario.")
Exception: El procedimiento no insertó el usuario.

2024-11-28 03:11:09 | ERROR | No se insertó el usuario.
2024-11-28 03:11:09 | ERROR | Traceback (most recent call last):
  File "/home/angel/Documentos/repositorios/api_flask_ecommerce/src/services/UsuariosService.py", line 103, in agregar_usuario
    raise Exception("No se insertó el usuario.")
Exception: No se insertó el usuario.

2024-11-28 03:13:53 | ERROR | No se insertó el usuario.
2024-11-28 03:13:53 | ERROR | Traceback (most recent call last):
  File "/home/angel/Documentos/repositorios/api_flask_ecommerce/src/services/UsuariosService.py", line 103, in agregar_usuario
    raise Exception("No se insertó el usuario.")
Exception: No se insertó el usuario.

2024-11-28 17:16:11 | ERROR | No se insertó el usuario.
2024-11-28 17:16:11 | ERROR | Traceback (most recent call last):
  File "/home/angel/Documentos/repositorios/api_flask_ecommerce/src/services/UsuariosService.py", line 103, in agregar_usuario
    raise Exception("No se insertó el usuario.")
Exception: No se insertó el usuario.

2024-11-28 17:36:44 | ERROR | Schema.load() missing 1 required positional argument: 'data'
2024-11-28 17:36:44 | ERROR | Traceback (most recent call last):
  File "/home/angel/Documentos/repositorios/api_flask_ecommerce/src/routes/UsuariosRoutes.py", line 63, in consultar_usuario
    datos_usuario = schema.load(request.json)
                    ^^^^^^^^^^^^^^^^^^^^^^^^^
TypeError: Schema.load() missing 1 required positional argument: 'data'

2024-11-28 17:40:13 | ERROR | Schema.load() missing 1 required positional argument: 'data'
2024-11-28 17:40:13 | ERROR | Traceback (most recent call last):
  File "/home/angel/Documentos/repositorios/api_flask_ecommerce/src/routes/UsuariosRoutes.py", line 63, in consultar_usuario
    datos_usuario = schema.load(request.json)
                    ^^^^^^^^^^^^^^^^^^^^^^^^^
TypeError: Schema.load() missing 1 required positional argument: 'data'

2024-11-28 17:40:48 | ERROR | Schema.load() missing 1 required positional argument: 'data'
2024-11-28 17:40:48 | ERROR | Traceback (most recent call last):
  File "/home/angel/Documentos/repositorios/api_flask_ecommerce/src/routes/UsuariosRoutes.py", line 63, in consultar_usuario
    datos_usuario = schema.load(request.json)
                    ^^^^^^^^^^^^^^^^^^^^^^^^^
TypeError: Schema.load() missing 1 required positional argument: 'data'

2024-11-28 17:43:02 | ERROR | Schema.load() missing 1 required positional argument: 'data'
2024-11-28 17:43:02 | ERROR | Traceback (most recent call last):
  File "/home/angel/Documentos/repositorios/api_flask_ecommerce/src/routes/UsuariosRoutes.py", line 63, in consultar_usuario
    datos_usuario = schema.load(request.json)
                    ^^^^^^^^^^^^^^^^^^^^^^^^^
TypeError: Schema.load() missing 1 required positional argument: 'data'

2024-11-28 17:45:50 | ERROR | Schema.load() missing 1 required positional argument: 'data'
2024-11-28 17:45:50 | ERROR | Traceback (most recent call last):
  File "/home/angel/Documentos/repositorios/api_flask_ecommerce/src/routes/UsuariosRoutes.py", line 63, in consultar_usuario
    datos_usuario = schema.load(request.json)
                    ^^^^^^^^^^^^^^^^^^^^^^^^^
TypeError: Schema.load() missing 1 required positional argument: 'data'

2024-11-28 17:48:41 | ERROR | Schema.load() missing 1 required positional argument: 'data'
2024-11-28 17:48:41 | ERROR | Traceback (most recent call last):
  File "/home/angel/Documentos/repositorios/api_flask_ecommerce/src/routes/UsuariosRoutes.py", line 63, in consultar_usuario
    datos_usuario = schema.load(request.json)
                    ^^^^^^^^^^^^^^^^^^^^^^^^^
TypeError: Schema.load() missing 1 required positional argument: 'data'

2024-11-28 18:05:30 | ERROR | Schema.load() missing 1 required positional argument: 'data'
2024-11-28 18:05:30 | ERROR | Traceback (most recent call last):
  File "/home/angel/Documentos/repositorios/api_flask_ecommerce/src/routes/UsuariosRoutes.py", line 63, in consultar_usuario
    datos_usuario = schema.load(request.json)
                    ^^^^^^^^^^^^^^^^^^^^^^^^^
TypeError: Schema.load() missing 1 required positional argument: 'data'

2024-11-29 01:15:10 | ERROR | 'str' object cannot be interpreted as an integer
2024-11-29 01:15:10 | ERROR | Traceback (most recent call last):
  File "/home/angel/Documentos/repositorios/api_flask_ecommerce/src/services/UsuariosService.py", line 27, in conseguir_usuarios
    contrasena = str(row[3]).split('\\','x')
                 ^^^^^^^^^^^^^^^^^^^^^^^^^^^
TypeError: 'str' object cannot be interpreted as an integer

2024-11-29 01:19:33 | ERROR | can only concatenate list (not "str") to list
2024-11-29 01:19:33 | ERROR | Traceback (most recent call last):
  File "/home/angel/Documentos/repositorios/api_flask_ecommerce/src/services/UsuariosService.py", line 29, in conseguir_usuarios
    contrasena + data
    ~~~~~~~~~~~^~~~~~
TypeError: can only concatenate list (not "str") to list

2024-11-29 01:25:31 | ERROR | No se pudo conectar a la base de datos.
2024-11-29 01:25:31 | ERROR | Traceback (most recent call last):
  File "/home/angel/Documentos/repositorios/api_flask_ecommerce/src/services/UsuariosService.py", line 19, in conseguir_usuarios
    raise Exception("No se pudo conectar a la base de datos.")
Exception: No se pudo conectar a la base de datos.

2024-11-29 01:26:00 | ERROR | No se pudo conectar a la base de datos.
2024-11-29 01:26:00 | ERROR | Traceback (most recent call last):
  File "/home/angel/Documentos/repositorios/api_flask_ecommerce/src/services/UsuariosService.py", line 19, in conseguir_usuarios
    raise Exception("No se pudo conectar a la base de datos.")
Exception: No se pudo conectar a la base de datos.

2024-11-29 01:27:27 | ERROR | No se pudo conectar a la base de datos.
2024-11-29 01:27:27 | ERROR | Traceback (most recent call last):
  File "/home/angel/Documentos/repositorios/api_flask_ecommerce/src/services/UsuariosService.py", line 19, in conseguir_usuarios
    raise Exception("No se pudo conectar a la base de datos.")
Exception: No se pudo conectar a la base de datos.

2024-11-29 13:03:26 | ERROR | No se pudo conectar a la base de datos.
2024-11-29 13:03:26 | ERROR | Traceback (most recent call last):
  File "/home/angel/Documentos/repositorios/api_flask_ecommerce/src/services/UsuariosService.py", line 19, in conseguir_usuarios
    raise Exception("No se pudo conectar a la base de datos.")
Exception: No se pudo conectar a la base de datos.

2024-11-29 13:57:08 | ERROR | 'NoneType' object has no attribute 'settimeout'
2024-11-29 13:57:08 | ERROR | Traceback (most recent call last):
  File "/home/angel/Documentos/repositorios/api_flask_ecommerce/src/services/AuthService.py", line 18, in login_user
    with connection.cursor() as cursor:
  File "/home/angel/Documentos/repositorios/api_flask_ecommerce/.api_venv/lib/python3.11/site-packages/pymysql/cursors.py", line 63, in __exit__
    self.close()
  File "/home/angel/Documentos/repositorios/api_flask_ecommerce/.api_venv/lib/python3.11/site-packages/pymysql/cursors.py", line 53, in close
    while self.nextset():
          ^^^^^^^^^^^^^^
  File "/home/angel/Documentos/repositorios/api_flask_ecommerce/.api_venv/lib/python3.11/site-packages/pymysql/cursors.py", line 98, in nextset
    return self._nextset(False)
           ^^^^^^^^^^^^^^^^^^^^
  File "/home/angel/Documentos/repositorios/api_flask_ecommerce/.api_venv/lib/python3.11/site-packages/pymysql/cursors.py", line 93, in _nextset
    conn.next_result(unbuffered=unbuffered)
  File "/home/angel/Documentos/repositorios/api_flask_ecommerce/.api_venv/lib/python3.11/site-packages/pymysql/connections.py", line 567, in next_result
    self._affected_rows = self._read_query_result(unbuffered=unbuffered)
                          ^^^^^^^^^^^^^^^^^^^^^^^^^^^^^^^^^^^^^^^^^^^^^^
  File "/home/angel/Documentos/repositorios/api_flask_ecommerce/.api_venv/lib/python3.11/site-packages/pymysql/connections.py", line 825, in _read_query_result
    result.read()
  File "/home/angel/Documentos/repositorios/api_flask_ecommerce/.api_venv/lib/python3.11/site-packages/pymysql/connections.py", line 1199, in read
    first_packet = self.connection._read_packet()
                   ^^^^^^^^^^^^^^^^^^^^^^^^^^^^^^
  File "/home/angel/Documentos/repositorios/api_flask_ecommerce/.api_venv/lib/python3.11/site-packages/pymysql/connections.py", line 744, in _read_packet
    packet_header = self._read_bytes(4)
                    ^^^^^^^^^^^^^^^^^^^
  File "/home/angel/Documentos/repositorios/api_flask_ecommerce/.api_venv/lib/python3.11/site-packages/pymysql/connections.py", line 779, in _read_bytes
    self._sock.settimeout(self._read_timeout)
    ^^^^^^^^^^^^^^^^^^^^^
AttributeError: 'NoneType' object has no attribute 'settimeout'

2024-11-29 17:13:19 | ERROR | The current Flask app is not registered with this 'SQLAlchemy' instance. Did you forget to call 'init_app', or did you create multiple 'SQLAlchemy' instances?
2024-11-29 17:13:19 | ERROR | Traceback (most recent call last):
  File "/home/angel/Documentos/repositorios/api_flask_ecommerce/src/services/AuthService.py", line 29, in login_user
    with db.engine.connect() as cursor :
         ^^^^^^^^^
  File "/home/angel/Documentos/repositorios/api_flask_ecommerce/.api_venv/lib/python3.11/site-packages/flask_sqlalchemy/extension.py", line 709, in engine
    return self.engines[None]
           ^^^^^^^^^^^^
  File "/home/angel/Documentos/repositorios/api_flask_ecommerce/.api_venv/lib/python3.11/site-packages/flask_sqlalchemy/extension.py", line 690, in engines
    raise RuntimeError(
RuntimeError: The current Flask app is not registered with this 'SQLAlchemy' instance. Did you forget to call 'init_app', or did you create multiple 'SQLAlchemy' instances?

2024-11-29 22:53:41 | ERROR | The current Flask app is not registered with this 'SQLAlchemy' instance. Did you forget to call 'init_app', or did you create multiple 'SQLAlchemy' instances?
2024-11-29 22:53:41 | ERROR | Traceback (most recent call last):
  File "/home/angel/Documentos/repositorios/api_flask_ecommerce/src/services/AuthService.py", line 29, in login_user
    with db.engine.connect() as cursor :
         ^^^^^^^^^
  File "/home/angel/Documentos/repositorios/api_flask_ecommerce/.api_venv/lib/python3.11/site-packages/flask_sqlalchemy/extension.py", line 709, in engine
    return self.engines[None]
           ^^^^^^^^^^^^
  File "/home/angel/Documentos/repositorios/api_flask_ecommerce/.api_venv/lib/python3.11/site-packages/flask_sqlalchemy/extension.py", line 690, in engines
    raise RuntimeError(
RuntimeError: The current Flask app is not registered with this 'SQLAlchemy' instance. Did you forget to call 'init_app', or did you create multiple 'SQLAlchemy' instances?

2024-11-29 22:57:04 | ERROR | The current Flask app is not registered with this 'SQLAlchemy' instance. Did you forget to call 'init_app', or did you create multiple 'SQLAlchemy' instances?
2024-11-29 22:57:04 | ERROR | Traceback (most recent call last):
  File "/home/angel/Documentos/repositorios/api_flask_ecommerce/src/services/AuthService.py", line 29, in login_user
    with db.engine.connect() as cursor :
         ^^^^^^^^^
  File "/home/angel/Documentos/repositorios/api_flask_ecommerce/.api_venv/lib/python3.11/site-packages/flask_sqlalchemy/extension.py", line 709, in engine
    return self.engines[None]
           ^^^^^^^^^^^^
  File "/home/angel/Documentos/repositorios/api_flask_ecommerce/.api_venv/lib/python3.11/site-packages/flask_sqlalchemy/extension.py", line 690, in engines
    raise RuntimeError(
RuntimeError: The current Flask app is not registered with this 'SQLAlchemy' instance. Did you forget to call 'init_app', or did you create multiple 'SQLAlchemy' instances?

2024-11-30 00:08:37 | ERROR | 'cryptography' package is required for sha256_password or caching_sha2_password auth methods
2024-11-30 00:08:37 | ERROR | Traceback (most recent call last):
  File "/home/angel/Documentos/repositorios/api_flask_ecommerce/src/services/AuthService.py", line 40, in login_user
    connection = get_pool_alchemy()
                 ^^^^^^^^^^^^^^^^^^
  File "/home/angel/Documentos/repositorios/api_flask_ecommerce/src/database/ejemploPoolConexion.py", line 21, in get_pool_alchemy
    connection = engine.connect()  # Obtiene una conexión del pool
                 ^^^^^^^^^^^^^^^^
  File "/home/angel/Documentos/repositorios/api_flask_ecommerce/.api_venv/lib/python3.11/site-packages/sqlalchemy/engine/base.py", line 3278, in connect
    return self._connection_cls(self)
           ^^^^^^^^^^^^^^^^^^^^^^^^^^
  File "/home/angel/Documentos/repositorios/api_flask_ecommerce/.api_venv/lib/python3.11/site-packages/sqlalchemy/engine/base.py", line 146, in __init__
    self._dbapi_connection = engine.raw_connection()
                             ^^^^^^^^^^^^^^^^^^^^^^^
  File "/home/angel/Documentos/repositorios/api_flask_ecommerce/.api_venv/lib/python3.11/site-packages/sqlalchemy/engine/base.py", line 3302, in raw_connection
    return self.pool.connect()
           ^^^^^^^^^^^^^^^^^^^
  File "/home/angel/Documentos/repositorios/api_flask_ecommerce/.api_venv/lib/python3.11/site-packages/sqlalchemy/pool/base.py", line 449, in connect
    return _ConnectionFairy._checkout(self)
           ^^^^^^^^^^^^^^^^^^^^^^^^^^^^^^^^
  File "/home/angel/Documentos/repositorios/api_flask_ecommerce/.api_venv/lib/python3.11/site-packages/sqlalchemy/pool/base.py", line 1263, in _checkout
    fairy = _ConnectionRecord.checkout(pool)
            ^^^^^^^^^^^^^^^^^^^^^^^^^^^^^^^^
  File "/home/angel/Documentos/repositorios/api_flask_ecommerce/.api_venv/lib/python3.11/site-packages/sqlalchemy/pool/base.py", line 712, in checkout
    rec = pool._do_get()
          ^^^^^^^^^^^^^^
  File "/home/angel/Documentos/repositorios/api_flask_ecommerce/.api_venv/lib/python3.11/site-packages/sqlalchemy/pool/impl.py", line 179, in _do_get
    with util.safe_reraise():
  File "/home/angel/Documentos/repositorios/api_flask_ecommerce/.api_venv/lib/python3.11/site-packages/sqlalchemy/util/langhelpers.py", line 146, in __exit__
    raise exc_value.with_traceback(exc_tb)
  File "/home/angel/Documentos/repositorios/api_flask_ecommerce/.api_venv/lib/python3.11/site-packages/sqlalchemy/pool/impl.py", line 177, in _do_get
    return self._create_connection()
           ^^^^^^^^^^^^^^^^^^^^^^^^^
  File "/home/angel/Documentos/repositorios/api_flask_ecommerce/.api_venv/lib/python3.11/site-packages/sqlalchemy/pool/base.py", line 390, in _create_connection
    return _ConnectionRecord(self)
           ^^^^^^^^^^^^^^^^^^^^^^^
  File "/home/angel/Documentos/repositorios/api_flask_ecommerce/.api_venv/lib/python3.11/site-packages/sqlalchemy/pool/base.py", line 674, in __init__
    self.__connect()
  File "/home/angel/Documentos/repositorios/api_flask_ecommerce/.api_venv/lib/python3.11/site-packages/sqlalchemy/pool/base.py", line 900, in __connect
    with util.safe_reraise():
  File "/home/angel/Documentos/repositorios/api_flask_ecommerce/.api_venv/lib/python3.11/site-packages/sqlalchemy/util/langhelpers.py", line 146, in __exit__
    raise exc_value.with_traceback(exc_tb)
  File "/home/angel/Documentos/repositorios/api_flask_ecommerce/.api_venv/lib/python3.11/site-packages/sqlalchemy/pool/base.py", line 896, in __connect
    self.dbapi_connection = connection = pool._invoke_creator(self)
                                         ^^^^^^^^^^^^^^^^^^^^^^^^^^
  File "/home/angel/Documentos/repositorios/api_flask_ecommerce/.api_venv/lib/python3.11/site-packages/sqlalchemy/engine/create.py", line 643, in connect
    return dialect.connect(*cargs, **cparams)
           ^^^^^^^^^^^^^^^^^^^^^^^^^^^^^^^^^^
  File "/home/angel/Documentos/repositorios/api_flask_ecommerce/.api_venv/lib/python3.11/site-packages/sqlalchemy/engine/default.py", line 621, in connect
    return self.loaded_dbapi.connect(*cargs, **cparams)
           ^^^^^^^^^^^^^^^^^^^^^^^^^^^^^^^^^^^^^^^^^^^^
  File "/home/angel/Documentos/repositorios/api_flask_ecommerce/.api_venv/lib/python3.11/site-packages/pymysql/connections.py", line 361, in __init__
    self.connect()
  File "/home/angel/Documentos/repositorios/api_flask_ecommerce/.api_venv/lib/python3.11/site-packages/pymysql/connections.py", line 669, in connect
    self._request_authentication()
  File "/home/angel/Documentos/repositorios/api_flask_ecommerce/.api_venv/lib/python3.11/site-packages/pymysql/connections.py", line 979, in _request_authentication
    auth_packet = _auth.caching_sha2_password_auth(self, auth_packet)
                  ^^^^^^^^^^^^^^^^^^^^^^^^^^^^^^^^^^^^^^^^^^^^^^^^^^^
  File "/home/angel/Documentos/repositorios/api_flask_ecommerce/.api_venv/lib/python3.11/site-packages/pymysql/_auth.py", line 267, in caching_sha2_password_auth
    data = sha2_rsa_encrypt(conn.password, conn.salt, conn.server_public_key)
           ^^^^^^^^^^^^^^^^^^^^^^^^^^^^^^^^^^^^^^^^^^^^^^^^^^^^^^^^^^^^^^^^^^
  File "/home/angel/Documentos/repositorios/api_flask_ecommerce/.api_venv/lib/python3.11/site-packages/pymysql/_auth.py", line 144, in sha2_rsa_encrypt
    raise RuntimeError(
RuntimeError: 'cryptography' package is required for sha256_password or caching_sha2_password auth methods

2024-11-30 00:29:21 | ERROR | List argument must consist only of tuples or dictionaries
2024-11-30 00:29:21 | ERROR | Traceback (most recent call last):
  File "/home/angel/Documentos/repositorios/api_flask_ecommerce/src/services/AuthService.py", line 41, in login_user
    result = connection.execute('call consultar_usuario(%s, %s)', (user.correo, user.contrasena))
             ^^^^^^^^^^^^^^^^^^^^^^^^^^^^^^^^^^^^^^^^^^^^^^^^^^^^^^^^^^^^^^^^^^^^^^^^^^^^^^^^^^^^
  File "/home/angel/Documentos/repositorios/api_flask_ecommerce/.api_venv/lib/python3.11/site-packages/sqlalchemy/engine/base.py", line 1412, in execute
    distilled_parameters = _distill_params_20(parameters)
                           ^^^^^^^^^^^^^^^^^^^^^^^^^^^^^^
  File "lib/sqlalchemy/cyextension/util.pyx", line 32, in sqlalchemy.cyextension.util._distill_params_20
  File "lib/sqlalchemy/cyextension/util.pyx", line 23, in sqlalchemy.cyextension.util._check_item
sqlalchemy.exc.ArgumentError: List argument must consist only of tuples or dictionaries

2024-11-30 00:31:06 | ERROR | List argument must consist only of tuples or dictionaries
2024-11-30 00:31:06 | ERROR | Traceback (most recent call last):
  File "/home/angel/Documentos/repositorios/api_flask_ecommerce/src/services/AuthService.py", line 41, in login_user
    result = connection.execute('call consultar_usuario(%s, %s)', (user.correo, user.contrasena))
             ^^^^^^^^^^^^^^^^^^^^^^^^^^^^^^^^^^^^^^^^^^^^^^^^^^^^^^^^^^^^^^^^^^^^^^^^^^^^^^^^^^^^
  File "/home/angel/Documentos/repositorios/api_flask_ecommerce/.api_venv/lib/python3.11/site-packages/sqlalchemy/engine/base.py", line 1412, in execute
    distilled_parameters = _distill_params_20(parameters)
                           ^^^^^^^^^^^^^^^^^^^^^^^^^^^^^^
  File "lib/sqlalchemy/cyextension/util.pyx", line 32, in sqlalchemy.cyextension.util._distill_params_20
  File "lib/sqlalchemy/cyextension/util.pyx", line 23, in sqlalchemy.cyextension.util._check_item
sqlalchemy.exc.ArgumentError: List argument must consist only of tuples or dictionaries

2024-11-30 00:34:05 | ERROR | List argument must consist only of tuples or dictionaries
2024-11-30 00:34:05 | ERROR | Traceback (most recent call last):
  File "/home/angel/Documentos/repositorios/api_flask_ecommerce/src/services/AuthService.py", line 41, in login_user
    result = connection.execute('call consultar_usuario(%s, %s)', (user.correo, user.contrasena))
             ^^^^^^^^^^^^^^^^^^^^^^^^^^^^^^^^^^^^^^^^^^^^^^^^^^^^^^^^^^^^^^^^^^^^^^^^^^^^^^^^^^^^
  File "/home/angel/Documentos/repositorios/api_flask_ecommerce/.api_venv/lib/python3.11/site-packages/sqlalchemy/engine/base.py", line 1412, in execute
    distilled_parameters = _distill_params_20(parameters)
                           ^^^^^^^^^^^^^^^^^^^^^^^^^^^^^^
  File "lib/sqlalchemy/cyextension/util.pyx", line 32, in sqlalchemy.cyextension.util._distill_params_20
  File "lib/sqlalchemy/cyextension/util.pyx", line 23, in sqlalchemy.cyextension.util._check_item
sqlalchemy.exc.ArgumentError: List argument must consist only of tuples or dictionaries

2024-11-30 01:38:34 | ERROR | Not an executable object: 'SELECT * FROM Categorias'
2024-11-30 01:38:34 | ERROR | Traceback (most recent call last):
  File "/home/angel/Documentos/repositorios/api_flask_ecommerce/.api_venv/lib/python3.11/site-packages/sqlalchemy/engine/base.py", line 1414, in execute
    meth = statement._execute_on_connection
           ^^^^^^^^^^^^^^^^^^^^^^^^^^^^^^^^
AttributeError: 'str' object has no attribute '_execute_on_connection'

The above exception was the direct cause of the following exception:

Traceback (most recent call last):
  File "/home/angel/Documentos/repositorios/api_flask_ecommerce/src/services/CategoriasService.py", line 16, in consultar_categorias
    cursor.execute('SELECT * FROM Categorias')
  File "/home/angel/Documentos/repositorios/api_flask_ecommerce/.api_venv/lib/python3.11/site-packages/sqlalchemy/engine/base.py", line 1416, in execute
    raise exc.ObjectNotExecutableError(statement) from err
sqlalchemy.exc.ObjectNotExecutableError: Not an executable object: 'SELECT * FROM Categorias'

2024-11-30 01:38:34 | ERROR | object of type 'NoneType' has no len()
2024-11-30 01:38:34 | ERROR | Traceback (most recent call last):
  File "/home/angel/Documentos/repositorios/api_flask_ecommerce/src/routes/CategoriasRoutes.py", line 14, in consultar_categorias
    if (len(categorias)>0):
        ^^^^^^^^^^^^^^^
TypeError: object of type 'NoneType' has no len()

2024-11-30 01:41:52 | ERROR | Not an executable object: 'SELECT * FROM categorias'
2024-11-30 01:41:52 | ERROR | Traceback (most recent call last):
  File "/home/angel/Documentos/repositorios/api_flask_ecommerce/.api_venv/lib/python3.11/site-packages/sqlalchemy/engine/base.py", line 1414, in execute
    meth = statement._execute_on_connection
           ^^^^^^^^^^^^^^^^^^^^^^^^^^^^^^^^
AttributeError: 'str' object has no attribute '_execute_on_connection'

The above exception was the direct cause of the following exception:

Traceback (most recent call last):
  File "/home/angel/Documentos/repositorios/api_flask_ecommerce/src/services/CategoriasService.py", line 16, in consultar_categorias
    cursor.execute('SELECT * FROM categorias')
  File "/home/angel/Documentos/repositorios/api_flask_ecommerce/.api_venv/lib/python3.11/site-packages/sqlalchemy/engine/base.py", line 1416, in execute
    raise exc.ObjectNotExecutableError(statement) from err
sqlalchemy.exc.ObjectNotExecutableError: Not an executable object: 'SELECT * FROM categorias'

2024-11-30 01:41:52 | ERROR | object of type 'NoneType' has no len()
2024-11-30 01:41:52 | ERROR | Traceback (most recent call last):
  File "/home/angel/Documentos/repositorios/api_flask_ecommerce/src/routes/CategoriasRoutes.py", line 14, in consultar_categorias
    if (len(categorias)>0):
        ^^^^^^^^^^^^^^^
TypeError: object of type 'NoneType' has no len()

2024-11-30 01:44:09 | ERROR | Not an executable object: 'SELECT * FROM categorias'
2024-11-30 01:44:09 | ERROR | Traceback (most recent call last):
  File "/home/angel/Documentos/repositorios/api_flask_ecommerce/.api_venv/lib/python3.11/site-packages/sqlalchemy/engine/base.py", line 1414, in execute
    meth = statement._execute_on_connection
           ^^^^^^^^^^^^^^^^^^^^^^^^^^^^^^^^
AttributeError: 'str' object has no attribute '_execute_on_connection'

The above exception was the direct cause of the following exception:

Traceback (most recent call last):
  File "/home/angel/Documentos/repositorios/api_flask_ecommerce/src/services/CategoriasService.py", line 16, in consultar_categorias
    cursor.execute('SELECT * FROM categorias')
  File "/home/angel/Documentos/repositorios/api_flask_ecommerce/.api_venv/lib/python3.11/site-packages/sqlalchemy/engine/base.py", line 1416, in execute
    raise exc.ObjectNotExecutableError(statement) from err
sqlalchemy.exc.ObjectNotExecutableError: Not an executable object: 'SELECT * FROM categorias'

2024-11-30 01:44:09 | ERROR | object of type 'NoneType' has no len()
2024-11-30 01:44:09 | ERROR | Traceback (most recent call last):
  File "/home/angel/Documentos/repositorios/api_flask_ecommerce/src/routes/CategoriasRoutes.py", line 14, in consultar_categorias
    if (len(categorias)>0):
        ^^^^^^^^^^^^^^^
TypeError: object of type 'NoneType' has no len()

